Workbook

Sheet Full BOM
A1: Industrial AMR — Full Bill of Materials
A2: Conceptual future physical BOM • Simulation-only academic project • No current procurement
A4: No. | B4: Category | C4: Component | D4: Part No. | E4: Brand | F4: Qty | G4: Supply / Rating | H4: Unit Power | I4: Total Power | J4: Communication | K4: Connects To | L4: Safety Role | M4: CAD Availability | N4: Datasheet Link | O4: CAD Link | P4: Preferred Supplier | Q4: Shop Link | R4: Listed Price | S4: Currency | T4: Price / Availability Status | U4: Checked | V4: Notes | W4: Unit Price THB | X4: Total THB
A5: 1 | B5: Compute | C5: AI computer | D5: Jetson Orin Nano Developer Kit 8GB | E5: NVIDIA | F5: 1 | G5: 9–20 VDC input | H5: 40 | I5: =F5*H5 -> 40 | J5: Gigabit Ethernet; USB; UART; CAN via adapter | K5: SCALANCE switch; Xsens; CAN adapter | L5: Non-safety navigation computer | M5: Official 3D model available | N5: https://developer.nvidia.com/embedded/learn/jetson-orin-nano-devkit-user-guide/index.html | O5: https://developer.nvidia.com/embedded/community/jetson-projects | P5: Cytron Thailand | Q5: https://th.cytron.io/p-nvidia-jetson-orin-nano-8gb-dev-kits | R5: 17,400.00 | S5: THB | T5: Thailand listing; price shown on product category page | U5: 2026-07-17 | V5: Candidate future physical compute only; current project runs on a laptop | W5: 17400 | X5: =IF(OR(W5="",F5=""),"",W5*F5) -> 17400
A6: 2 | B6: Motion | C6: Dual-axis BLDC servo driver | D6: ZLAC8030D | E6: ZLTECH | F6: 1 | G6: 24–48 VDC; 30 A/channel class; 60 A peak stated | H6: 25 | I6: =F6*H6 -> 25 | J6: CANopen CiA 301/402; Modbus RTU RS-485 | K6: Jetson through isolated CAN; two hub motors | L6: Programmable enable only; not certified STO | M6: Manufacturer dimensional drawing / CAD model | N6: https://www.zlingkj.com/en/robot-hub-servo-motor-series/550676 | O6: https://www.zlingkj.com/en/robot-hub-servo-motor-series/550676 | P6: ZLTECH direct / China ZLTECH | Q6: https://www.zlingkj.com/en/robot-hub-servo-motor-series/550676 | R6: RFQ | T6: Direct manufacturer quotation required | U6: 2026-07-17 | V6: Final bus-voltage and regeneration check deferred by user | X6: =IF(OR(W6="",F6=""),"",W6*F6)
A7: 3 | B7: Motion | C7: Left hub BLDC servo motor | D7: ZLLG10ASM800 V2.0 | E7: ZLTECH | F7: 1 | G7: 48 V; 800 W; 8.5 A rated; 25 A peak | H7: 800 | I7: =F7*H7 -> 800 | J7: Motor phases; Hall/4096-line magnetic encoder | K7: ZLAC8030D channel 1 | L7: None | M7: Official dimensional drawing | N7: https://www.zlingkj.com/en/robot-hub-servo-motor-series/565267 | O7: https://www.zlingkj.com/en/robot-hub-servo-motor-series/565267 | P7: ZLTECH direct / China ZLTECH | Q7: https://www.zlingkj.com/en/robot-hub-servo-motor-series/565267 | R7: RFQ | T7: Direct manufacturer quotation required | U7: 2026-07-17 | V7: 10-inch drive wheel | X7: =IF(OR(W7="",F7=""),"",W7*F7)
A8: 4 | B8: Motion | C8: Right hub BLDC servo motor | D8: ZLLG10ASM800 V2.0 | E8: ZLTECH | F8: 1 | G8: 48 V; 800 W; 8.5 A rated; 25 A peak | H8: 800 | I8: =F8*H8 -> 800 | J8: Motor phases; Hall/4096-line magnetic encoder | K8: ZLAC8030D channel 2 | L8: None | M8: Official dimensional drawing | N8: https://www.zlingkj.com/en/robot-hub-servo-motor-series/565267 | O8: https://www.zlingkj.com/en/robot-hub-servo-motor-series/565267 | P8: ZLTECH direct / China ZLTECH | Q8: https://www.zlingkj.com/en/robot-hub-servo-motor-series/565267 | R8: RFQ | T8: Direct manufacturer quotation required | U8: 2026-07-17 | V8: 10-inch drive wheel | X8: =IF(OR(W8="",F8=""),"",W8*F8)
A9: 5 | B9: Navigation | C9: Navigation LiDAR front | D9: MRS1104C-111011 / 1081208 | E9: SICK | F9: 1 | G9: 10–30 VDC; typ. 13 W; max. 37 W | H9: 37 | I9: =F9*H9 -> 37 | J9: Ethernet TCP/IP; CoLa; ROS 2 driver configuration TBD | K9: Jetson through SCALANCE switch | L9: Not safety-rated for personnel protection | M9: Official mechanical drawing and product data available | N9: https://www.sick.com/media/pdf/4/44/044/dataSheet_MRS1104C-111011_1081208_en.pdf | O9: https://www.sick.com/MRS1000 | P9: SICK Thailand / authorised distributor | R9: RFQ | T9: Request quotation for exact order number 1081208 | U9: 2026-07-24 | V9: Simulated front-left 3D LiDAR characteristics; no physical purchase; exact pose TBD
A10: 6 | B10: Navigation | C10: Navigation LiDAR rear | D10: MRS1104C-111011 / 1081208 | E10: SICK | F10: 1 | G10: 10–30 VDC; typ. 13 W; max. 37 W | H10: 37 | I10: =F10*H10 -> 37 | J10: Ethernet TCP/IP; CoLa; ROS 2 driver configuration TBD | K10: Jetson through SCALANCE switch | L10: Not safety-rated for personnel protection | M10: Official mechanical drawing and product data available | N10: https://www.sick.com/media/pdf/4/44/044/dataSheet_MRS1104C-111011_1081208_en.pdf | O10: https://www.sick.com/MRS1000 | P10: SICK Thailand / authorised distributor | R10: RFQ | T10: Request quotation for exact order number 1081208 | U10: 2026-07-24 | V10: Simulated rear-right 3D LiDAR characteristics; no physical purchase; exact pose TBD
A11: 7 | B11: Localization | C11: Industrial IMU | D11: MTi-8-5A-DK | E11: Xsens | F11: 1 | G11: 5 V via USB / DK supply | H11: 2 | I11: =F11*H11 -> 2 | J11: USB 2.0; UART; RS-232 depending interface | K11: Jetson | L11: Non-safety localization input | M11: Official mechanical drawing | N11: https://www.movella.com/products/sensor-modules/xsens-mti-8 | O11: https://www.movella.com/products/sensor-modules/xsens-mti-8 | P11: Movella / Xsens distributor | Q11: https://www.movella.com/products/sensor-modules/xsens-mti-8 | R11: RFQ | T11: Development kit pricing is quotation-based | U11: 2026-07-17 | V11: Candidate future MTi-8-5A-DK only; current project uses Gazebo-generated IMU data | X11: =IF(OR(W11="",F11=""),"",W11*F11)
A12: 8 | B12: PLC & safety | C12: Fail-safe PLC CPU | D12: 6ES7214-1AF40-0XB0 | E12: Siemens | F12: 1 | G12: 20.4–28.8 VDC | H12: 12 | I12: =F12*H12 -> 12 | J12: PROFINET; PROFIsafe; Ethernet | K12: SCALANCE; HMI; safety scanners; Jetson | L12: Runs safety and standard PLC logic | M12: Official M-CAD/E-CAD | N12: https://sieportal.siemens.com/en-ww/products-services/detail/6ES7214-1AF40-0XB0 | O12: https://mall.industry.siemens.com/mall/en/WW/Catalog/Product/6ES7214-1AF40-0XB0 | P12: RS Thailand | Q12: https://th.rs-online.com/web/p/plcs-programmable-logic-controllers/2008960 | R12: 39,047.45 | S12: THB | T12: Ex VAT | U12: 2026-07-17 | V12: Candidate future PLC only; PLC authority and safety-state behavior are simulated | W12: 39047.45 | X12: =IF(OR(W12="",F12=""),"",W12*F12) -> 39047.45
A13: 9 | B13: PLC & safety | C13: Fail-safe digital input module | D13: 6ES7226-6BA32-0XB0 | E13: Siemens | F13: 1 | G13: 24 VDC | H13: 5 | I13: =F13*H13 -> 5 | J13: Backplane + PROFIsafe processing | K13: CPU 1214FC | L13: E-stops, bumper, interlocks, feedback | M13: Official M-CAD/E-CAD | N13: https://support.industry.siemens.com/cs/products/6es7226-6ba32-0xb0 | O13: https://mall.industry.siemens.com/mall/en/WW/Catalog/Product/6ES7226-6BA32-0XB0 | P13: MISUMI Thailand | Q13: https://th.misumi-ec.com/en/vona2/detail/222304577158/?HissuCode=6ES7226-6BA32-0XB0 | R13: 6,235.29 | S13: THB | T13: Listed price; 45-day lead time shown | U13: 2026-07-17 | V13: 16 fail-safe inputs | W13: 6235.29 | X13: =IF(OR(W13="",F13=""),"",W13*F13) -> 6235.29
A14: 10 | B14: PLC & safety | C14: Fail-safe digital output module | D14: 6ES7226-6DA32-0XB0 | E14: Siemens | F14: 1 | G14: 24 VDC; 2 A/output | H14: 5 | I14: =F14*H14 -> 5 | J14: Backplane + PROFIsafe processing | K14: CPU 1214FC; safety contactors | L14: Redundant safe output control | M14: Official M-CAD/E-CAD | N14: https://support.industry.siemens.com/teddatasheet/?caller=SIOS&format=pdf&language=en&mlfbs=6ES7226-6DA32-0XB0 | O14: https://mall.industry.siemens.com/mall/en/WW/Catalog/Product/6ES7226-6DA32-0XB0 | P14: RS / Automation24 | Q14: https://www.automation24.com/siemens-sm-1226-6es7226-6da32-0-xb0 | R14: 206.10 | S14: EUR | T14: International supplier; plus VAT and shipping | U14: 2026-07-17 | V14: 4 fail-safe outputs | X14: =IF(OR(W14="",F14=""),"",W14*F14)
A15: 11 | B15: PLC & safety | C15: SIMATIC memory card | D15: 6ES7954-8LC03-0AA0 | E15: Siemens | F15: 1 | G15: 24 MB | H15: 0 | I15: =F15*H15 -> 0 | J15: PLC memory interface | K15: CPU 1214FC | L15: Program/firmware backup | M15: Official M-CAD/E-CAD | N15: https://mall.industry.siemens.com/mall/en/WW/Catalog/Product/6ES7954-8LC03-0AA0 | O15: https://mall.industry.siemens.com/mall/en/WW/Catalog/Product/6ES7954-8LC03-0AA0 | P15: Siemens distributor / RS | Q15: https://sieportal.siemens.com/en-ww/products-services/detail/6ES7954-8LF04-0AA0 | R15: RFQ | T15: Use current 24 MB card revision; local quote recommended | U15: 2026-07-17 | V15: Recommended for serviceability | X15: =IF(OR(W15="",F15=""),"",W15*F15)
A16: 12 | B16: Networking | C16: Managed industrial Ethernet switch | D16: 6GK5216-0BA00-2AC2 / SCALANCE XC216 | E16: Siemens | F16: 1 | G16: 24 VDC redundant input | H16: 15 | I16: =F16*H16 -> 15 | J16: 16× 10/100 Ethernet; PROFINET device; VLAN/RSTP/SNMP | K16: All Ethernet and PROFINET devices | L16: Network diagnostics; not a safety controller | M16: Official M-CAD/E-CAD | N16: https://support.industry.siemens.com/cs/products/6gk5216-0ba00-2ac2/scalance-xc216 | O16: https://mall.industry.siemens.com/mall/en/WW/Catalog/Product/6GK5216-0BA00-2AC2 | P16: MISUMI Thailand | Q16: https://th.misumi-ec.com/en/vona2/detail/222304577574/?HissuCode=6GK5216-0BA00-2AC2 | R16: 51,411.76 | S16: THB | T16: Listed price | U16: 2026-07-17 | V16: 16 ports leaves service/expansion ports | W16: 51411.76 | X16: =IF(OR(W16="",F16=""),"",W16*F16) -> 51411.76
A17: 13 | B17: Communication | C17: Isolated USB-to-CAN interface | D17: PCAN-USB Pro FD IPEH-004061 | E17: PEAK-System | F17: 1 | G17: USB powered | H17: 3 | I17: =F17*H17 -> 3 | J17: CAN / CAN FD over USB | K17: Jetson to ZLAC8030D | L17: Non-safety motor command path | M17: Mechanical drawing available | N17: https://www.peak-system.com/PCAN-USB-Pro-FD.366.0.html?&L=1 | O17: https://www.peak-system.com/produktcd/Pdf/English/PCAN-USB-Pro-FD_UserMan_eng.pdf | P17: Techsquare Thailand | Q17: https://www.techsquare.co.th/product/peak-system-pcan-usb-pro-fd-can-can-fd-and-lin-interface-for-high-speed-usb-2-0/ | R17: RFQ | T17: Thailand supplier; request quotation | U17: 2026-07-17 | V17: Use classic CAN for ZLAC8030D CANopen | X17: =IF(OR(W17="",F17=""),"",W17*F17)
A18: 14 | B18: Operator interface | C18: 7-inch Basic HMI | D18: 6AV2123-2GB03-0AX0 / KTP700 Basic PN | E18: Siemens | F18: 1 | G18: 24 VDC | H18: 8 | I18: =F18*H18 -> 8 | J18: PROFINET/Ethernet | K18: PLC through SCALANCE | L18: Displays status; not safety-rated | M18: Official M-CAD/E-CAD | N18: https://mall.industry.siemens.com/mall/en/WW/Catalog/Product/6AV2123-2GB03-0AX0 | O18: https://mall.industry.siemens.com/mall/en/WW/Catalog/Product/6AV2123-2GB03-0AX0 | P18: MISUMI Thailand | Q18: https://th.misumi-ec.com/th/vona2/detail/222304577686/?HissuCode=6AV2123-2GB03-0AX0 | R18: 21,137.50 | S18: THB | T18: Listed price; 2-day lead time shown | U18: 2026-07-17 | V18: Local diagnostics and manual operation | W18: 21137.5 | X18: =IF(OR(W18="",F18=""),"",W18*F18) -> 21137.5
A19: 15 | B19: Power conversion | C19: 48 V nominal to 24 V industrial DC/DC | D19: DDR-240C-24 | E19: MEAN WELL | F19: 1 | G19: 33.6–67.2 VDC in; 24 V 10 A out | H19: 240 | I19: =F19*H19 -> 240 | J19: Power only; alarm contact if fitted | K19: 24 V PLC, controls, networking, and verified sensor loads | L19: Maintains the 24 V control rail from the traction battery | M19: Official 3D model/drawing | N19: https://www.meanwell.com/Upload/PDF/DDR-240/DDR-240-spec.pdf | O19: https://www.meanwell.com/webapp/product/search.aspx?prod=DDR-240 | P19: DigiKey Thailand | Q19: https://www.digikey.co.th/en/products/detail/mean-well-usa-inc/DDR-240C-24/9602713 | R19: 3,297.93 | S19: THB | T19: Listed unit price; stock varies | U19: 2026-07-17 | V19: Size based on worst-case 24 V load; verify final thermal margin | W19: 3297.93 | X19: =IF(OR(W19="",F19=""),"",W19*F19) -> 3297.93
A20: 16 | B20: Power conversion | C20: 48 V nominal to 12 V industrial DC/DC | D20: DDR-60L-12 | E20: MEAN WELL | F20: 1 | G20: 18–75 VDC in; 12 V 5 A out | H20: 60 | I20: =F20*H20 -> 60 | J20: Power only | K20: Jetson Orin Nano | L20: Separate compute rail | M20: Official 3D model/drawing | N20: https://www.meanwell.com/Upload/PDF/DDR-60/DDR-60-spec.pdf | O20: https://www.meanwell.com/webapp/product/search.aspx?prod=DDR-60 | P20: DigiKey Thailand / MEAN WELL distributor | Q20: https://www.digikey.co.th/en/products/filter/dc-dc-converters/922?s=N4IgTCBcDaIC4AsCmAnApgAgDIHsB2A5iALoC%2BQA | R20: RFQ | T20: Search exact DDR-60L-12; request quote if not stocked | U20: 2026-07-17 | V20: Dedicated Jetson supply | X20: =IF(OR(W20="",F20=""),"",W20*F20)
A21: 17 | B21: Power source | C21: Assembled traction battery with BMS | D21: User-supplied 48 V LiFePO4 / exact model TBD | E21: User supplied | F21: 1 | G21: 48/51.2 V nominal; capacity and mass TBD | H21: 0 | I21: =F21*H21 -> 0 | J21: CAN or RS-485 if available; otherwise discrete status; exact BMS TBD | K21: Main DC bus | L21: Energy source; BMS protection | M21: User-supplied CAD | N21: User supplied | O21: User supplied | P21: User supplied | R21: Owned | T21: Battery and BMS already owned by user | U21: 2026-07-17 | V21: Battery capacity, mass, BMS interface, and exact model remain open | X21: =IF(OR(W21="",F21=""),"",W21*F21)
A22: 18 | B22: Charging | C22: Matched LiFePO4 charger | D22: User-supplied / exact model TBD | E22: TBD | F22: 1 | G22: Match battery/BMS | H22: 0 | I22: =F22*H22 -> 0 | J22: CAN/RS-485 or dry contacts if available | K22: Battery; PLC status input | L22: Charging interlock | M22: Require STEP/2D drawing | N22: TBD | O22: TBD | P22: Battery supplier / charger manufacturer | R22: TBD | T22: Match existing battery/BMS charge profile | U22: 2026-07-17 | V22: Exact model depends on existing battery | X22: =IF(OR(W22="",F22=""),"",W22*F22)
A23: 19 | B23: Power safety | C23: Main DC fuse | D23: MEGA / MIDI DC fuse, final rating TBD | E23: Littelfuse | F23: 1 | G23: ≥ battery max voltage; provisional 80–100 A | H23: 0 | I23: =F23*H23 -> 0 | J23: None | K23: Battery positive bus | L23: Primary short-circuit protection | M23: Official CAD available | N23: https://www.littelfuse.com/products/fuses/automotive-passenger-car/high-current-fuses/mega | O23: https://www.littelfuse.com/products/fuses/automotive-passenger-car/high-current-fuses/mega | P23: RS Thailand / Littelfuse distributor | Q23: https://th.rs-online.com/web/c/fuses-circuit-breakers/fuses/automotive-fuses/ | R23: RFQ | T23: Final fuse rating still TBD; quote after rating is frozen | U23: 2026-07-17 | V23: Final size after current-limit confirmation | X23: =IF(OR(W23="",F23=""),"",W23*F23)
A24: 20 | B24: Power safety | C24: Main battery disconnect | D24: m-Series 6006 | E24: Blue Sea Systems | F24: 1 | G24: 48 VDC class; current rating per datasheet | H24: 0 | I24: =F24*H24 -> 0 | J24: Manual mechanical isolation | K24: Battery main bus | L24: Lockable service isolation | M24: Official dimensional drawing | N24: https://www.bluesea.com/products/6006/m-Series_Battery_Switch_ON-OFF_with_Knob_-_Red | O24: https://www.bluesea.com/products/6006/m-Series_Battery_Switch_ON-OFF_with_Knob_-_Red | P24: Blue Sea authorised reseller | Q24: https://www.bluesea.com/products/6006/m-Series_Battery_Switch_ON-OFF_with_Knob_-_Red | R24: RFQ | T24: Local marine/electrical distributor quotation | U24: 2026-07-17 | V24: Choose DC rating with margin | X24: =IF(OR(W24="",F24=""),"",W24*F24)
A25: 21 | B25: Power safety | C25: Main safety contactor K1 | D25: EV200AAANA | E25: TE Connectivity / Kilovac | F25: 1 | G25: 12–900 VDC switching class; 24 V coil variant preferred | H25: 8 | I25: =F25*H25 -> 8 | J25: 24 V coil + auxiliary feedback | K25: F-DQ; drive DC bus | L25: Redundant propulsion power isolation | M25: Official 3D CAD | N25: https://www.te.com/usa-en/product-1618002-7.html | O25: https://www.te.com/usa-en/product-1618002-7.html | P25: DigiKey Thailand | Q25: https://www.digikey.co.th/th/products/detail/te-connectivity-aerospace-defense-and-marine/EV200AAANA/1209930 | R25: 5,636.60 | S25: THB | T25: Listed unit price | U25: 2026-07-17 | V25: Verify exact coil suffix and auxiliary contact | W25: 5636.6 | X25: =IF(OR(W25="",F25=""),"",W25*F25) -> 5636.6
A26: 22 | B26: Power safety | C26: Main safety contactor K2 | D26: EV200AAANA | E26: TE Connectivity / Kilovac | F26: 1 | G26: 12–900 VDC switching class; 24 V coil variant preferred | H26: 8 | I26: =F26*H26 -> 8 | J26: 24 V coil + auxiliary feedback | K26: F-DQ; drive DC bus | L26: Second redundant propulsion isolation channel | M26: Official 3D CAD | N26: https://www.te.com/usa-en/product-1618002-7.html | O26: https://www.te.com/usa-en/product-1618002-7.html | P26: DigiKey Thailand | Q26: https://www.digikey.co.th/th/products/detail/te-connectivity-aerospace-defense-and-marine/EV200AAANA/1209930 | R26: 5,636.60 | S26: THB | T26: Listed unit price | U26: 2026-07-17 | V26: Use guided/monitored feedback architecture | W26: 5636.6 | X26: =IF(OR(W26="",F26=""),"",W26*F26) -> 5636.6
A27: 23 | B27: Power safety | C27: Precharge contactor/relay | D27: G7L-2A-TUBJ-CB DC24 | E27: Omron | F27: 1 | G27: 24 VDC coil | H27: 2 | I27: =F27*H27 -> 2 | J27: 24 V discrete output | K27: PLC integrated DO; precharge branch | L27: Limits DC-link inrush | M27: Official CAD/drawing | N27: https://components.omron.com/us-en/products/relays/G7L | O27: https://components.omron.com/us-en/products/relays/G7L | P27: AutomationCAD Thailand / Omron distributor | Q27: https://www.automationcad.com/product/2448/relay-omron-g7l-2a-tub-%E0%B8%9E%E0%B8%B2%E0%B8%A7%E0%B9%80%E0%B8%A7%E0%B8%AD%E0%B8%A3%E0%B9%8C%E0%B8%A3%E0%B8%B5%E0%B9%80%E0%B8%A5%E0%B8%A2%E0%B9%8C-220vac | R27: 495.00 | S27: THB | T27: Reference series price; verify exact DC24 coil part | U27: 2026-07-17 | V27: Pair with calculated precharge resistor | W27: 495 | X27: =IF(OR(W27="",F27=""),"",W27*F27) -> 495
A28: 24 | B28: Power safety | C28: Precharge resistor | D28: HSC100 100R J | E28: ARCOL / Ohmite equivalent | F28: 1 | G28: 100 Ω, 100 W pulse-capable | H28: 0 | I28: =F28*H28 -> 0 | J28: None | K28: Across main contactor precharge path | L28: Limits capacitor charging current | M28: Official 3D CAD/drawing | N28: https://www.ohmite.com/hsc-series/ | O28: https://www.ohmite.com/hsc-series/ | P28: Ohmite / ARCOL distributor | Q28: https://www.ohmite.com/hsc-series/ | R28: RFQ | T28: Exact resistance and pulse rating must be recalculated | U28: 2026-07-17 | V28: Resistance/pulse energy must be recalculated from driver capacitance | X28: =IF(OR(W28="",F28=""),"",W28*F28)
A29: 25 | B29: Safety controls | C29: Dual-channel emergency stop | D29: XB5AS8445 | E29: Schneider Electric | F29: 2 | G29: 2 NC safety contacts; 22 mm | H29: 0 | I29: =F29*H29 -> 0 | J29: Dual-channel dry contacts | K29: SM 1226 F-DI | L29: Emergency-stop input | M29: Official 3D CAD | N29: https://www.se.com/ww/en/product/XB5AS8445/ | O29: https://www.se.com/ww/en/product/XB5AS8445/ | P29: MISUMI Thailand | Q29: https://th.misumi-ec.com/th/vona2/detail/222302146798/?HissuCode=XB5AS8445 | R29: 389.13 | S29: THB | T29: Promotional price shown; verify current cart price | U29: 2026-07-17 | V29: One on each accessible side | W29: 389.13 | X29: =IF(OR(W29="",F29=""),"",W29*F29) -> 778.26
A30: 26 | B30: Safety controls | C30: Safety reset pushbutton | D30: XB5AA31 | E30: Schneider Electric | F30: 1 | G30: 24 V control circuit | H30: 0 | I30: =F30*H30 -> 0 | J30: Discrete 24 V input | K30: PLC integrated DI / F-DI as designed | L30: Manual reset acknowledgement | M30: Official 3D CAD | N30: https://www.se.com/ww/en/product/XB5AA31/ | O30: https://www.se.com/ww/en/product/XB5AA31/ | P30: MISUMI Thailand | Q30: https://th.misumi-ec.com/th/vona2/detail/222302146798/?HissuCode=XB5AS8445 | R30: 389.13 | S30: THB | T30: Promotional price shown; verify current cart price | U30: 2026-07-17 | V30: Blue or illuminated version may be selected | W30: 389.13 | X30: =IF(OR(W30="",F30=""),"",W30*F30) -> 389.13
A31: 27 | B31: Safety controls | C31: Keyed mode selector | D31: XB5AG33 | E31: Schneider Electric | F31: 1 | G31: 3-position maintained | H31: 0 | I31: =F31*H31 -> 0 | J31: Discrete 24 V inputs | K31: PLC integrated DI | L31: Auto / Manual / Service mode selection | M31: Official 3D CAD | N31: https://www.se.com/ww/en/product/XB5AG33/ | O31: https://www.se.com/ww/en/product/XB5AG33/ | P31: MISUMI Thailand | Q31: https://th.misumi-ec.com/th/vona2/detail/222005697014/?HissuCode=XB5AA31 | R31: 179.12 | S31: THB | T31: Promotional price shown | U31: 2026-07-17 | V31: Key removable position to be chosen | W31: 179.12 | X31: =IF(OR(W31="",F31=""),"",W31*F31) -> 179.12
A32: 28 | B32: Safety controls | C32: Safety bumper edge | D32: SE-P40 series, exact length TBD | E32: Schmersal | F32: 1 | G32: Dual-channel safety edge | H32: 0 | I32: =F32*H32 -> 0 | J32: Dual-channel safety contact | K32: SM 1226 F-DI | L32: Contact protection around chassis | M32: Official CAD/drawings | N32: https://products.schmersal.com/en_US/safety-edges-1000006325.html | O32: https://products.schmersal.com/en_US/safety-edges-1000006325.html | P32: MISUMI Thailand | Q32: https://th.misumi-ec.com/en/vona2/detail/222304492389/?HissuCode=XB5AG33 | R32: 527.07 | S32: THB | T32: Promotional price shown; 60-day lead time | U32: 2026-07-17 | V32: Final profile length follows chassis CAD | W32: 527.07 | X32: =IF(OR(W32="",F32=""),"",W32*F32) -> 527.07
A33: 29 | B33: Status | C33: Modular signal tower | D33: LR6-302WJNW-RYG | E33: PATLITE | F33: 1 | G33: 24 VDC | H33: 5 | I33: =F33*H33 -> 5 | J33: PLC discrete outputs | K33: PLC integrated DO | L33: Visual operating-state indication | M33: Official 3D CAD | N33: https://www.patlite.com/product/detail0000000648.html | O33: https://www.patlite.com/product/detail0000000648.html | P33: Schmersal Thailand / authorised distributor | Q33: https://products.schmersal.com/en_US/safety-edges-1000006325.html | R33: RFQ | T33: Length-specific quotation required | U33: 2026-07-17 | V33: Red/yellow/green; add blue if desired | X33: =IF(OR(W33="",F33=""),"",W33*F33)
A34: 30 | B34: Status | C34: Electronic sounder | D34: BKV-24 | E34: PATLITE | F34: 1 | G34: 24 VDC | H34: 4 | I34: =F34*H34 -> 4 | J34: PLC discrete output | K34: PLC integrated DO | L34: Movement/fault warning | M34: Official 3D CAD | N34: https://www.patlite.com/product/ | O34: https://www.patlite.com/product/ | P34: PATLITE Thailand / RS Thailand | Q34: https://th.rs-online.com/web/p/signal-towers/1701789 | R34: RFQ | T34: Exact LR6 colour/module configuration requires quote | U34: 2026-07-17 | V34: Exact tone/version may be adjusted | X34: =IF(OR(W34="",F34=""),"",W34*F34)
A35: 31 | B35: Wireless | C35: Industrial Wi-Fi client/access point | D35: SCALANCE W774-1 RJ45 / exact regional variant | E35: Siemens | F35: 1 | G35: 24 VDC | H35: 12 | I35: =F35*H35 -> 12 | J35: Industrial WLAN + Ethernet | K35: SCALANCE switch; fleet network | L35: Non-safety fleet link | M35: Official M-CAD/E-CAD | N35: https://www.siemens.com/global/en/products/automation/industrial-communication/industrial-wireless-lan/scalance-w.html | O35: https://mall.industry.siemens.com/mall/en/WW/Catalog/Products/10254145 | P35: PATLITE Thailand | Q35: https://www.patlite.co.th/ | R35: RFQ | T35: Exact BKV-24 model availability should be confirmed | U35: 2026-07-17 | V35: Select Thailand radio approval variant | X35: =IF(OR(W35="",F35=""),"",W35*F35)
A36: 32 | B36: Docking | C36: Dock presence photoelectric sensor | D36: E3Z-D62 2M | E36: Omron | F36: 1 | G36: 12–24 VDC | H36: 1 | I36: =F36*H36 -> 1 | J36: PNP discrete output | K36: PLC integrated DI | L36: Dock-confirmation input | M36: Official 3D CAD/drawing | N36: https://automation.omron.com/en/us/products/family/E3Z | O36: https://automation.omron.com/en/us/products/family/E3Z | P36: Siemens distributor / RS | Q36: https://support.industry.siemens.com/cs/products/6gk5774-1fx00-0aa0/scalance-w774-1-rj45 | R36: RFQ | T36: Select Thailand-approved radio variant before ordering | U36: 2026-07-17 | V36: Exact optical arrangement depends on dock | X36: =IF(OR(W36="",F36=""),"",W36*F36)
A37: 33 | B37: Docking | C37: Charging contact set | D37: ROBOFIX / exact current class TBD | E37: SCHUNK | F37: 1 | G37: Match charger current | H37: 0 | I37: =F37*H37 -> 0 | J37: Power contacts + optional pilot contacts | K37: Battery charger; PLC | L37: Automatic charging interface | M37: Official CAD available | N37: https://schunk.com/us/en/automation-technology/components-for-mobile-robots/robofix/c/PGR_7046 | O37: https://schunk.com/us/en/automation-technology/components-for-mobile-robots/robofix/c/PGR_7046 | P37: MISUMI Thailand / Omron distributor | Q37: https://th.misumi-ec.com/th/vona2/detail/221000398342/?HissuCode=E3Z-D61+2M | R37: 2,597.62 | S37: THB | T37: Closest listed E3Z-D61; verify exact PNP/NPN model required | U37: 2026-07-17 | V37: Select current and mechanical stroke after charger choice | W37: 2597.62 | X37: =IF(OR(W37="",F37=""),"",W37*F37) -> 2597.62
A38: 34 | B38: Thermal | C38: Cabinet filter fan | D38: SK 3237.100 or suitable size | E38: Rittal | F38: 1 | G38: 24 VDC fan variant | H38: 15 | I38: =F38*H38 -> 15 | J38: Thermostat-switched 24 V | K38: 24 V auxiliary rail | L38: Cabinet cooling | M38: Official 3D CAD | N38: https://www.rittal.com/com-en/products/PG0168KLIMA1/PG0169KLIMA1/PRO13213 | O38: https://www.rittal.com/com-en/products/PG0168KLIMA1/PG0169KLIMA1/PRO13213 | P38: SCHUNK Thailand | Q38: https://schunk.com/us/en/automation-technology/components-for-mobile-robots/robofix/c/PGR_7046 | R38: RFQ | T38: Current class and contact geometry require quotation | U38: 2026-07-17 | V38: Size after enclosure thermal calculation | X38: =IF(OR(W38="",F38=""),"",W38*F38)
A39: 35 | B39: Thermal | C39: Cabinet thermostat | D39: SK 3110.000 | E39: Rittal | F39: 1 | G39: 24 V control | H39: 0 | I39: =F39*H39 -> 0 | J39: Dry contact | K39: Cooling fan / PLC DI | L39: Temperature-controlled ventilation | M39: Official 3D CAD | N39: https://www.rittal.com/com-en/products/PG0168KLIMA1/PG0200KLIMA1/PRO12018 | O39: https://www.rittal.com/com-en/products/PG0168KLIMA1/PG0200KLIMA1/PRO12018 | P39: Rittal Thailand | Q39: https://www.rittal.com/th-th/products/PG0168KLIMA1/PG0169KLIMA1/PRO13213 | R39: RFQ | T39: Size-dependent local quotation | U39: 2026-07-17 | V39: Mechanical thermostat | X39: =IF(OR(W39="",F39=""),"",W39*F39)
A40: 36 | B40: Mechanical | C40: Heavy-duty swivel caster | D40: LEVINA 5370PJP100P62 | E40: TENTE | F40: 4 | G40: Load rating per caster datasheet | H40: 0 | I40: =F40*H40 -> 0 | J40: None | K40: Chassis | L40: Passive support wheel | M40: Official 3D CAD | N40: https://www.tente.com/en-us/products/levina/ | O40: https://www.tente.com/en-us/products/levina/ | P40: Rittal Thailand | Q40: https://www.rittal.com/th-th/products/PG0168KLIMA1/PG0200KLIMA1/PRO12018 | R40: RFQ | T40: Local quotation | U40: 2026-07-17 | V40: Four casters confirmed; dimensions, swivel geometry, load distribution, and floor suitability require verification | X40: =IF(OR(W40="",F40=""),"",W40*F40)
A41: 37 | B41: Mechanical | C41: Electrical enclosure | D41: AE series, size TBD | E41: Rittal | F41: 1 | G41: Industrial enclosure; IP rating as required | H41: 0 | I41: =F41*H41 -> 0 | J41: None | K41: All DIN-rail electrical components | L41: Physical protection | M41: Official 3D CAD | N41: https://www.rittal.com/com-en/products/PG0002SCHRANK1/PG0021SCHRANK1 | O41: https://www.rittal.com/com-en/products/PG0002SCHRANK1/PG0021SCHRANK1 | P41: TENTE Thailand / distributor | Q41: https://www.tente.com/en-us/products/levina/ | R41: RFQ | T41: Final caster load rating and wheel size required | U41: 2026-07-17 | V41: Select after layout study | X41: =IF(OR(W41="",F41=""),"",W41*F41)
...

Sheet Power Budget
A1: Conceptual Future Physical AMR Power Budget
A2: Reference sizing only • Current project is laptop-based simulation with no physical power system
A3: Rail | B3: Load Group | C3: Source Rows | D3: Calculated Load (W) | E3: Design Margin | F3: Required Capacity (W) | G3: Selected Supply | H3: Selected Capacity (W) | I3: Headroom (W) | J3: Status | L3: Key Calculated Totals
A4: 24 V | B4: Safety + PLC + networking + MRS1000 sensors | C4: Verified current 24 V component loads | D4: 174 | E4: 0.25 | F4: 217.5 | G4: MEAN WELL DDR-240C-24 | H4: 240 | I4: 22.5 | J4: Provisional OK with 25% margin; recheck final variants and accessories | L4: 24 V calculated load | M4: 174 | N4: W
A5: 12 V | B5: Jetson compute rail | C5: 1 | D5: ='Full BOM'!I5 -> 40 | E5: 0.25 | F5: =D5*(1+E5) -> 50 | G5: MEAN WELL DDR-60L-12 | H5: 60 | I5: =IF(H5=0,"",H5-F5) -> 10 | J5: =IF(H5>=F5,"OK","UPSIZE") -> OK | L5: 24 V required with margin | M5: 217.5 | N5: W
A6: Traction bus | B6: Hub motors + motor driver | C6: 2–4 | D6: ='Full BOM'!I6+'Full BOM'!I7+'Full BOM'!I8 -> 1625 | E6: 0.2 | F6: =D6*(1+E6) -> 1950 | G6: Battery direct to ZLAC8030D | H6: 0 | I6: =IF(H6=0,"",H6-F6) | J6: Voltage compatibility deferred | L6: 12 V calculated load | M6: =D5 -> 40 | N6: W
L7: Traction rated load | M7: =D6 -> 1625 | N7: W
L8: Stored battery energy | M8: TBD | N8: Wh

Sheet Communication Matrix
A1: AMR Communication Matrix
A2: Conceptual physical interfaces and simulated authority/data paths • No current hardware
A4: From | B4: To | C4: Physical Interface | D4: Protocol | E4: Primary Data | F4: Safety-Critical? | G4: Gateway / Adapter | H4: Verified Compatibility | I4: Notes
A5: Jetson Orin Nano | B5: S7-1200F | C5: Ethernet via SCALANCE | D5: OPC UA / S7 TCP / Modbus TCP (choose one) | E5: Robot state, mission state, heartbeat, faults | F5: No safety commands | G5: None | H5: Yes at Ethernet level | I5: PLC keeps final drive-permission authority
A6: MRS1104C-111011 front | B6: Jetson Orin Nano | C6: Ethernet via SCALANCE | D6: SICK CoLa over TCP/IP; ROS 2 driver TBD | E6: Multi-layer LiDAR data for SLAM/navigation/costmaps | F6: No; not safety-rated for personnel protection | G6: None | H6: Official interface verified; ROS integration not bench-validated | I6: Front-left mounting concept; exact pose and ROS 2 driver configuration TBD
A7: MRS1104C-111011 rear | B7: Jetson Orin Nano | C7: Ethernet via SCALANCE | D7: SICK CoLa over TCP/IP; ROS 2 driver TBD | E7: Multi-layer LiDAR data for SLAM/navigation/costmaps | F7: No; not safety-rated for personnel protection | G7: None | H7: Official interface verified; ROS integration not bench-validated | I7: Rear-right mounting concept; exact pose and ROS 2 driver configuration TBD
A8: Xsens MTi-8 | B8: Jetson Orin Nano | C8: USB 2.0 | D8: Xsens MTData2 / XDA | E8: IMU orientation, angular rate, acceleration | F8: No | G8: USB cable | H8: Yes | I8: ROS 2 Xsens driver required
A9: Jetson Orin Nano | B9: ZLAC8030D | C9: USB-to-CAN | D9: CANopen CiA 301 / CiA 402 | E9: Wheel velocity commands, encoder feedback, faults | F9: No; safety handled separately | G9: PEAK PCAN-USB Pro FD | H9: Yes | I9: Jetson is sole motion-command master
A10: ZLAC8030D | B10: Left hub motor | C10: Motor phases + encoder harness | D10: Vendor motor/encoder interface | E10: Torque and feedback | F10: No certified safety | G10: Direct harness | H10: Yes by matched ZLTECH family | I10: Verify exact connector pinout
A11: ZLAC8030D | B11: Right hub motor | C11: Motor phases + encoder harness | D11: Vendor motor/encoder interface | E11: Torque and feedback | F11: No certified safety | G11: Direct harness | H11: Yes by matched ZLTECH family | I11: Verify exact connector pinout
A12: S7-1200F F-DQ | B12: Safety contactors K1/K2 | C12: 24 V hardwired | D12: Dual-channel safe outputs | E12: Remove drive-bus energy | F12: Yes | G12: Interposing interface only if coil current requires | H12: Yes conceptually | I12: Validate safety architecture and feedback monitoring
A13: E-stops / bumper | B13: S7-1200F F-DI | C13: 24 V hardwired dual-channel | D13: Fail-safe digital inputs | E13: Emergency stop and contact protection | F13: Yes | G13: None | H13: Yes | I13: Use test pulses/approved wiring
A14: HMI KTP700 | B14: S7-1200F | C14: Ethernet via SCALANCE | D14: PROFINET | E14: Operator commands, alarms, diagnostics | F14: No | G14: None | H14: Yes | I14: Safety reset must follow validated logic
A15: Wi-Fi client | B15: Jetson / fleet server | C15: Ethernet + WLAN | D15: TCP/IP / ROS 2 DDS through controlled network | E15: Fleet missions and telemetry | F15: No | G15: SCALANCE W client | H15: Yes | I15: Do not place safety functions on Wi-Fi
... A18: SCALANCE XC216 | B18: All Ethernet devices | C18: 16× RJ45 10/100 | D18: Ethernet, PROFINET, SNMP, VLAN/RSTP | E18: Network transport and diagnostics | F18: Transports PROFIsafe but does not execute safety | G18: None | H18: Yes | I18: 100 Mbps is sufficient for listed devices

Sheet Design Notes
A1: Industrial AMR Conceptual BOM — Simulation-Only Academic Project
A2: Topic | B2: Decision | C2: Reason | D2: Open item | E2: Owner | F2: Priority
A3: PLC | B3: CPU 1214FC + SM1226 F-DI + SM1226 F-DQ | C3: Emergency stops, bumper, interlocks, and monitored shutdown require fail-safe processing | D3: Safety program and PL/SIL validation | E3: Controls | F3: High
A4: Standard PLC I/O | B4: No normal extension module | C4: CPU onboard I/O expected to cover non-safety buttons, indicators, dock and fan | D4: Final I/O count during electrical design | E4: Controls | F4: Medium
A5: Perception LiDARs | B5: 2× SICK MRS1104C-111011 / 1081208 | C5: Frozen perception architecture for SLAM, navigation, and costmaps | D5: Firmware, ROS 2 driver configuration, IP plan, time synchronization, and six-degree-of-freedom poses | E5: Perception | F5: High
A6: Motor control | B6: 1× ZLAC8030D dual-axis | C6: Matched ZLTECH motor family; CANopen/RS-485 | D6: Voltage/regeneration deliberately deferred | E6: Motion | F6: High
A7: Ethernet | B7: SCALANCE XC216 managed 16-port switch | C7: Candidate port count for PLC, Jetson, two LiDARs, HMI, Wi-Fi, and service access | D7: IP plan, VLANs, PROFINET naming | E7: Network | F7: Medium
A8: 24 V power | B8: DDR-240C-24 selected | C8: Current verified 24 V loads total 174 W; 25% design margin requires 217.5 W | D8: 22.5 W residual headroom; recheck exact HMI, Wi-Fi, fan, accessories, wiring losses, and simultaneous load states | E8: Electrical | F8: High
A9: 12 V power | B9: DDR-60L-12 selected | C9: Dedicated 60 W rail for Jetson | D9: Confirm USB peripheral load | E9: Electrical | F9: Medium
A10: Battery/BMS | B10: User supplied | C10: User explicitly requested to stop blocking BOM on battery details | D10: Only mechanical envelope/CAD needed for final assembly | E10: Mechanical | F10: Low
A11: CAD | B11: Official manufacturer CAD where available | C11: Needed for simulation assembly | D11: Some user-supplied/TBD items may need simplified CAD | E11: CAD | F11: Medium
A12: CAD links | B12: Clickable datasheet and CAD/model-page links added to the Full BOM | C12: Makes manufacturer drawings and 3D model pages easier to open | D12: Some suppliers provide a model page rather than a direct STEP file | E12: CAD | F12: Medium
A13: Current scope | B13: Laptop-based ROS 2 Humble + Gazebo Harmonic simulation | C13: No physical procurement, installation, commissioning, or certification | D13: Install and validate Gazebo Harmonic in the software setup phase | E13: Software | F13: High
... A15: Safety compliance | B15: No PL/SIL claim; provisional PL d Category 3 concept only | C15: Academic simulation cannot validate physical functional safety | D15: Future risk assessment and competent formal validation required | E15: Safety | F15: High

Sheet Procurement Summary
A1: Conceptual Procurement Reference — No Current Purchasing
A3: Metric | B3: Value
A4: Rows with Thailand THB price | B4: =COUNTIF('Full BOM'!S5:S42,"THB") -> 14
A5: Rows requiring RFQ/TBD | B5: =COUNTIF('Full BOM'!R5:R42,"RFQ")+COUNTIF('Full BOM'!R5:R42,"TBD") -> 22
A6: Known THB subtotal | B6: =SUM('Full BOM'!X5:X42) -> 154769.33
A7: Price check date | B7: 2026-07-24 architecture update; prices not rechecked
A8: Preferred order | B8: Thailand vendor → MISUMI → RS → authorised distributor → international
A9: VAT / shipping | B9: Prices are mixed: some exclude VAT and most exclude shipping
A10: Important | B10: Simulation-only project; supplier/price realignment deferred. Revalidate all entries before any future purchase.
